[2024-07-15T04:30:32.565+0000] {local_task_job_runner.py:120} INFO - ::group::Pre task execution logs
[2024-07-15T04:30:32.590+0000] {taskinstance.py:2076} INFO - Dependencies all met for dep_context=non-requeueable deps ti=<TaskInstance: etl_pipeline.load_to_postgresql scheduled__2024-07-14T00:00:00+00:00 [queued]>
[2024-07-15T04:30:32.597+0000] {taskinstance.py:2076} INFO - Dependencies all met for dep_context=requeueable deps ti=<TaskInstance: etl_pipeline.load_to_postgresql scheduled__2024-07-14T00:00:00+00:00 [queued]>
[2024-07-15T04:30:32.598+0000] {taskinstance.py:2306} INFO - Starting attempt 2 of 2
[2024-07-15T04:30:32.618+0000] {taskinstance.py:2330} INFO - Executing <Task(PythonOperator): load_to_postgresql> on 2024-07-14 00:00:00+00:00
[2024-07-15T04:30:32.628+0000] {warnings.py:112} WARNING - /home/***/.local/lib/python3.12/site-packages/***/task/task_runner/standard_task_runner.py:61: DeprecationWarning: This process (pid=125) is multi-threaded, use of fork() may lead to deadlocks in the child.
  pid = os.fork()

[2024-07-15T04:30:32.630+0000] {standard_task_runner.py:63} INFO - Started process 127 to run task
[2024-07-15T04:30:32.630+0000] {standard_task_runner.py:90} INFO - Running: ['***', 'tasks', 'run', 'etl_pipeline', 'load_to_postgresql', 'scheduled__2024-07-14T00:00:00+00:00', '--job-id', '219', '--raw', '--subdir', 'DAGS_FOLDER/demo.py', '--cfg-path', '/tmp/tmpvr60fiic']
[2024-07-15T04:30:32.631+0000] {standard_task_runner.py:91} INFO - Job 219: Subtask load_to_postgresql
[2024-07-15T04:30:32.674+0000] {task_command.py:426} INFO - Running <TaskInstance: etl_pipeline.load_to_postgresql scheduled__2024-07-14T00:00:00+00:00 [running]> on host 37d6808b0cee
[2024-07-15T04:30:32.749+0000] {taskinstance.py:2648} INFO - Exporting env vars: AIRFLOW_CTX_DAG_EMAIL='your_email@example.com' AIRFLOW_CTX_DAG_OWNER='***' AIRFLOW_CTX_DAG_ID='etl_pipeline' AIRFLOW_CTX_TASK_ID='load_to_postgresql' AIRFLOW_CTX_EXECUTION_DATE='2024-07-14T00:00:00+00:00' AIRFLOW_CTX_TRY_NUMBER='2' AIRFLOW_CTX_DAG_RUN_ID='scheduled__2024-07-14T00:00:00+00:00'
[2024-07-15T04:30:32.750+0000] {taskinstance.py:430} INFO - ::endgroup::
[2024-07-15T04:30:32.752+0000] {taskinstance.py:441} INFO - ::group::Post task execution logs
[2024-07-15T04:30:32.753+0000] {taskinstance.py:2905} ERROR - Task failed with exception
Traceback (most recent call last):
  File "/home/airflow/.local/lib/python3.12/site-packages/airflow/models/taskinstance.py", line 465, in _execute_task
    result = _execute_callable(context=context, **execute_callable_kwargs)
             ^^^^^^^^^^^^^^^^^^^^^^^^^^^^^^^^^^^^^^^^^^^^^^^^^^^^^^^^^^^^^
  File "/home/airflow/.local/lib/python3.12/site-packages/airflow/models/taskinstance.py", line 432, in _execute_callable
    return execute_callable(context=context, **execute_callable_kwargs)
           ^^^^^^^^^^^^^^^^^^^^^^^^^^^^^^^^^^^^^^^^^^^^^^^^^^^^^^^^^^^^
  File "/home/airflow/.local/lib/python3.12/site-packages/airflow/models/baseoperator.py", line 401, in wrapper
    return func(self, *args, **kwargs)
           ^^^^^^^^^^^^^^^^^^^^^^^^^^^
  File "/home/airflow/.local/lib/python3.12/site-packages/airflow/operators/python.py", line 235, in execute
    return_value = self.execute_callable()
                   ^^^^^^^^^^^^^^^^^^^^^^^
  File "/home/airflow/.local/lib/python3.12/site-packages/airflow/operators/python.py", line 252, in execute_callable
    return self.python_callable(*self.op_args, **self.op_kwargs)
           ^^^^^^^^^^^^^^^^^^^^^^^^^^^^^^^^^^^^^^^^^^^^^^^^^^^^^
  File "/opt/airflow/dags/demo.py", line 56, in load_to_postgresql
    df_merged = pd.read_csv('/tmp/df_merged.csv')
                ^^^^^^^^^^^^^^^^^^^^^^^^^^^^^^^^^
  File "/home/airflow/.local/lib/python3.12/site-packages/pandas/io/parsers/readers.py", line 948, in read_csv
    return _read(filepath_or_buffer, kwds)
           ^^^^^^^^^^^^^^^^^^^^^^^^^^^^^^^
  File "/home/airflow/.local/lib/python3.12/site-packages/pandas/io/parsers/readers.py", line 611, in _read
    parser = TextFileReader(filepath_or_buffer, **kwds)
             ^^^^^^^^^^^^^^^^^^^^^^^^^^^^^^^^^^^^^^^^^^
  File "/home/airflow/.local/lib/python3.12/site-packages/pandas/io/parsers/readers.py", line 1448, in __init__
    self._engine = self._make_engine(f, self.engine)
                   ^^^^^^^^^^^^^^^^^^^^^^^^^^^^^^^^^
  File "/home/airflow/.local/lib/python3.12/site-packages/pandas/io/parsers/readers.py", line 1705, in _make_engine
    self.handles = get_handle(
                   ^^^^^^^^^^^
  File "/home/airflow/.local/lib/python3.12/site-packages/pandas/io/common.py", line 863, in get_handle
    handle = open(
             ^^^^^
FileNotFoundError: [Errno 2] No such file or directory: '/tmp/df_merged.csv'
[2024-07-15T04:30:32.760+0000] {taskinstance.py:1206} INFO - Marking task as FAILED. dag_id=etl_pipeline, task_id=load_to_postgresql, run_id=scheduled__2024-07-14T00:00:00+00:00, execution_date=20240714T000000, start_date=20240715T043032, end_date=20240715T043032
[2024-07-15T04:30:32.775+0000] {standard_task_runner.py:110} ERROR - Failed to execute job 219 for task load_to_postgresql ([Errno 2] No such file or directory: '/tmp/df_merged.csv'; 127)
[2024-07-15T04:30:32.804+0000] {local_task_job_runner.py:240} INFO - Task exited with return code 1
[2024-07-15T04:30:32.826+0000] {taskinstance.py:3503} INFO - 0 downstream tasks scheduled from follow-on schedule check
[2024-07-15T04:30:32.841+0000] {local_task_job_runner.py:222} INFO - ::endgroup::
