[2024-07-14T16:24:29.456+0000] {local_task_job_runner.py:120} INFO - ::group::Pre task execution logs
[2024-07-14T16:24:29.557+0000] {taskinstance.py:2076} INFO - Dependencies all met for dep_context=non-requeueable deps ti=<TaskInstance: etl_pipeline.load_to_postgresql manual__2024-07-14T16:24:25.097023+00:00 [queued]>
[2024-07-14T16:24:29.587+0000] {taskinstance.py:2076} INFO - Dependencies all met for dep_context=requeueable deps ti=<TaskInstance: etl_pipeline.load_to_postgresql manual__2024-07-14T16:24:25.097023+00:00 [queued]>
[2024-07-14T16:24:29.597+0000] {taskinstance.py:2306} INFO - Starting attempt 1 of 2
[2024-07-14T16:24:29.643+0000] {taskinstance.py:2330} INFO - Executing <Task(PythonOperator): load_to_postgresql> on 2024-07-14 16:24:25.097023+00:00
[2024-07-14T16:24:29.657+0000] {warnings.py:112} WARNING - /home/***/.local/lib/python3.12/site-packages/***/task/task_runner/standard_task_runner.py:61: DeprecationWarning: This process (pid=206) is multi-threaded, use of fork() may lead to deadlocks in the child.
  pid = os.fork()

[2024-07-14T16:24:29.680+0000] {standard_task_runner.py:63} INFO - Started process 212 to run task
[2024-07-14T16:24:29.682+0000] {standard_task_runner.py:90} INFO - Running: ['***', 'tasks', 'run', 'etl_pipeline', 'load_to_postgresql', 'manual__2024-07-14T16:24:25.097023+00:00', '--job-id', '203', '--raw', '--subdir', 'DAGS_FOLDER/demo.py', '--cfg-path', '/tmp/tmp3uj5ymeg']
[2024-07-14T16:24:29.683+0000] {standard_task_runner.py:91} INFO - Job 203: Subtask load_to_postgresql
[2024-07-14T16:24:29.765+0000] {task_command.py:426} INFO - Running <TaskInstance: etl_pipeline.load_to_postgresql manual__2024-07-14T16:24:25.097023+00:00 [running]> on host 37d6808b0cee
[2024-07-14T16:24:29.912+0000] {taskinstance.py:2648} INFO - Exporting env vars: AIRFLOW_CTX_DAG_EMAIL='your_email@example.com' AIRFLOW_CTX_DAG_OWNER='***' AIRFLOW_CTX_DAG_ID='etl_pipeline' AIRFLOW_CTX_TASK_ID='load_to_postgresql' AIRFLOW_CTX_EXECUTION_DATE='2024-07-14T16:24:25.097023+00:00' AIRFLOW_CTX_TRY_NUMBER='1' AIRFLOW_CTX_DAG_RUN_ID='manual__2024-07-14T16:24:25.097023+00:00'
[2024-07-14T16:24:29.921+0000] {taskinstance.py:430} INFO - ::endgroup::
[2024-07-14T16:24:29.928+0000] {taskinstance.py:441} INFO - ::group::Post task execution logs
[2024-07-14T16:24:29.928+0000] {taskinstance.py:2905} ERROR - Task failed with exception
Traceback (most recent call last):
  File "/home/airflow/.local/lib/python3.12/site-packages/airflow/models/taskinstance.py", line 465, in _execute_task
    result = _execute_callable(context=context, **execute_callable_kwargs)
             ^^^^^^^^^^^^^^^^^^^^^^^^^^^^^^^^^^^^^^^^^^^^^^^^^^^^^^^^^^^^^
  File "/home/airflow/.local/lib/python3.12/site-packages/airflow/models/taskinstance.py", line 432, in _execute_callable
    return execute_callable(context=context, **execute_callable_kwargs)
           ^^^^^^^^^^^^^^^^^^^^^^^^^^^^^^^^^^^^^^^^^^^^^^^^^^^^^^^^^^^^
  File "/home/airflow/.local/lib/python3.12/site-packages/airflow/models/baseoperator.py", line 401, in wrapper
    return func(self, *args, **kwargs)
           ^^^^^^^^^^^^^^^^^^^^^^^^^^^
  File "/home/airflow/.local/lib/python3.12/site-packages/airflow/operators/python.py", line 235, in execute
    return_value = self.execute_callable()
                   ^^^^^^^^^^^^^^^^^^^^^^^
  File "/home/airflow/.local/lib/python3.12/site-packages/airflow/operators/python.py", line 252, in execute_callable
    return self.python_callable(*self.op_args, **self.op_kwargs)
           ^^^^^^^^^^^^^^^^^^^^^^^^^^^^^^^^^^^^^^^^^^^^^^^^^^^^^
  File "/opt/airflow/dags/demo.py", line 56, in load_to_postgresql
    df_merged = pd.read_csv('/tmp/df_merged.csv')
                ^^^^^^^^^^^^^^^^^^^^^^^^^^^^^^^^^
  File "/home/airflow/.local/lib/python3.12/site-packages/pandas/io/parsers/readers.py", line 948, in read_csv
    return _read(filepath_or_buffer, kwds)
           ^^^^^^^^^^^^^^^^^^^^^^^^^^^^^^^
  File "/home/airflow/.local/lib/python3.12/site-packages/pandas/io/parsers/readers.py", line 611, in _read
    parser = TextFileReader(filepath_or_buffer, **kwds)
             ^^^^^^^^^^^^^^^^^^^^^^^^^^^^^^^^^^^^^^^^^^
  File "/home/airflow/.local/lib/python3.12/site-packages/pandas/io/parsers/readers.py", line 1448, in __init__
    self._engine = self._make_engine(f, self.engine)
                   ^^^^^^^^^^^^^^^^^^^^^^^^^^^^^^^^^
  File "/home/airflow/.local/lib/python3.12/site-packages/pandas/io/parsers/readers.py", line 1705, in _make_engine
    self.handles = get_handle(
                   ^^^^^^^^^^^
  File "/home/airflow/.local/lib/python3.12/site-packages/pandas/io/common.py", line 863, in get_handle
    handle = open(
             ^^^^^
FileNotFoundError: [Errno 2] No such file or directory: '/tmp/df_merged.csv'
[2024-07-14T16:24:29.989+0000] {taskinstance.py:1206} INFO - Marking task as UP_FOR_RETRY. dag_id=etl_pipeline, task_id=load_to_postgresql, run_id=manual__2024-07-14T16:24:25.097023+00:00, execution_date=20240714T162425, start_date=20240714T162429, end_date=20240714T162429
[2024-07-14T16:24:30.037+0000] {standard_task_runner.py:110} ERROR - Failed to execute job 203 for task load_to_postgresql ([Errno 2] No such file or directory: '/tmp/df_merged.csv'; 212)
[2024-07-14T16:24:30.058+0000] {local_task_job_runner.py:240} INFO - Task exited with return code 1
[2024-07-14T16:24:30.078+0000] {taskinstance.py:3503} INFO - 0 downstream tasks scheduled from follow-on schedule check
[2024-07-14T16:24:30.087+0000] {local_task_job_runner.py:222} INFO - ::endgroup::
