[2024-07-14T16:31:43.090+0000] {local_task_job_runner.py:120} INFO - ::group::Pre task execution logs
[2024-07-14T16:31:43.107+0000] {taskinstance.py:2076} INFO - Dependencies all met for dep_context=non-requeueable deps ti=<TaskInstance: etl_pipeline.clean_data manual__2024-07-14T16:31:36.174573+00:00 [queued]>
[2024-07-14T16:31:43.113+0000] {taskinstance.py:2076} INFO - Dependencies all met for dep_context=requeueable deps ti=<TaskInstance: etl_pipeline.clean_data manual__2024-07-14T16:31:36.174573+00:00 [queued]>
[2024-07-14T16:31:43.113+0000] {taskinstance.py:2306} INFO - Starting attempt 1 of 2
[2024-07-14T16:31:43.129+0000] {taskinstance.py:2330} INFO - Executing <Task(PythonOperator): clean_data> on 2024-07-14 16:31:36.174573+00:00
[2024-07-14T16:31:43.136+0000] {warnings.py:112} WARNING - /home/***/.local/lib/python3.12/site-packages/***/task/task_runner/standard_task_runner.py:61: DeprecationWarning: This process (pid=317) is multi-threaded, use of fork() may lead to deadlocks in the child.
  pid = os.fork()

[2024-07-14T16:31:43.137+0000] {standard_task_runner.py:63} INFO - Started process 319 to run task
[2024-07-14T16:31:43.138+0000] {standard_task_runner.py:90} INFO - Running: ['***', 'tasks', 'run', 'etl_pipeline', 'clean_data', 'manual__2024-07-14T16:31:36.174573+00:00', '--job-id', '210', '--raw', '--subdir', 'DAGS_FOLDER/demo.py', '--cfg-path', '/tmp/tmp5b15z9aw']
[2024-07-14T16:31:43.139+0000] {standard_task_runner.py:91} INFO - Job 210: Subtask clean_data
[2024-07-14T16:31:43.184+0000] {task_command.py:426} INFO - Running <TaskInstance: etl_pipeline.clean_data manual__2024-07-14T16:31:36.174573+00:00 [running]> on host 37d6808b0cee
[2024-07-14T16:31:43.260+0000] {taskinstance.py:2648} INFO - Exporting env vars: AIRFLOW_CTX_DAG_EMAIL='your_email@example.com' AIRFLOW_CTX_DAG_OWNER='***' AIRFLOW_CTX_DAG_ID='etl_pipeline' AIRFLOW_CTX_TASK_ID='clean_data' AIRFLOW_CTX_EXECUTION_DATE='2024-07-14T16:31:36.174573+00:00' AIRFLOW_CTX_TRY_NUMBER='1' AIRFLOW_CTX_DAG_RUN_ID='manual__2024-07-14T16:31:36.174573+00:00'
[2024-07-14T16:31:43.261+0000] {taskinstance.py:430} INFO - ::endgroup::
[2024-07-14T16:31:43.276+0000] {taskinstance.py:441} INFO - ::group::Post task execution logs
[2024-07-14T16:31:43.277+0000] {taskinstance.py:2905} ERROR - Task failed with exception
Traceback (most recent call last):
  File "/home/airflow/.local/lib/python3.12/site-packages/pandas/core/indexes/base.py", line 3791, in get_loc
    return self._engine.get_loc(casted_key)
           ^^^^^^^^^^^^^^^^^^^^^^^^^^^^^^^^
  File "index.pyx", line 152, in pandas._libs.index.IndexEngine.get_loc
  File "index.pyx", line 181, in pandas._libs.index.IndexEngine.get_loc
  File "pandas/_libs/hashtable_class_helper.pxi", line 7080, in pandas._libs.hashtable.PyObjectHashTable.get_item
  File "pandas/_libs/hashtable_class_helper.pxi", line 7088, in pandas._libs.hashtable.PyObjectHashTable.get_item
KeyError: 'Company'

The above exception was the direct cause of the following exception:

Traceback (most recent call last):
  File "/home/airflow/.local/lib/python3.12/site-packages/airflow/models/taskinstance.py", line 465, in _execute_task
    result = _execute_callable(context=context, **execute_callable_kwargs)
             ^^^^^^^^^^^^^^^^^^^^^^^^^^^^^^^^^^^^^^^^^^^^^^^^^^^^^^^^^^^^^
  File "/home/airflow/.local/lib/python3.12/site-packages/airflow/models/taskinstance.py", line 432, in _execute_callable
    return execute_callable(context=context, **execute_callable_kwargs)
           ^^^^^^^^^^^^^^^^^^^^^^^^^^^^^^^^^^^^^^^^^^^^^^^^^^^^^^^^^^^^
  File "/home/airflow/.local/lib/python3.12/site-packages/airflow/models/baseoperator.py", line 401, in wrapper
    return func(self, *args, **kwargs)
           ^^^^^^^^^^^^^^^^^^^^^^^^^^^
  File "/home/airflow/.local/lib/python3.12/site-packages/airflow/operators/python.py", line 235, in execute
    return_value = self.execute_callable()
                   ^^^^^^^^^^^^^^^^^^^^^^^
  File "/home/airflow/.local/lib/python3.12/site-packages/airflow/operators/python.py", line 252, in execute_callable
    return self.python_callable(*self.op_args, **self.op_kwargs)
           ^^^^^^^^^^^^^^^^^^^^^^^^^^^^^^^^^^^^^^^^^^^^^^^^^^^^^
  File "/opt/airflow/dags/demo.py", line 31, in clean_data
    df_xlsx['Company'] = df_xlsx['Company'].apply(lambda x: process.extractOne(x, df_csv['Company'])[0])
                         ~~~~~~~^^^^^^^^^^^
  File "/home/airflow/.local/lib/python3.12/site-packages/pandas/core/frame.py", line 3893, in __getitem__
    indexer = self.columns.get_loc(key)
              ^^^^^^^^^^^^^^^^^^^^^^^^^
  File "/home/airflow/.local/lib/python3.12/site-packages/pandas/core/indexes/base.py", line 3798, in get_loc
    raise KeyError(key) from err
KeyError: 'Company'
[2024-07-14T16:31:43.307+0000] {taskinstance.py:1206} INFO - Marking task as UP_FOR_RETRY. dag_id=etl_pipeline, task_id=clean_data, run_id=manual__2024-07-14T16:31:36.174573+00:00, execution_date=20240714T163136, start_date=20240714T163143, end_date=20240714T163143
[2024-07-14T16:31:43.323+0000] {standard_task_runner.py:110} ERROR - Failed to execute job 210 for task clean_data ('Company'; 319)
[2024-07-14T16:31:43.355+0000] {local_task_job_runner.py:240} INFO - Task exited with return code 1
[2024-07-14T16:31:43.374+0000] {taskinstance.py:3503} INFO - 0 downstream tasks scheduled from follow-on schedule check
[2024-07-14T16:31:43.380+0000] {local_task_job_runner.py:222} INFO - ::endgroup::
