[2024-07-14T10:38:30.352+0000] {local_task_job_runner.py:120} INFO - ::group::Pre task execution logs
[2024-07-14T10:38:30.382+0000] {taskinstance.py:2076} INFO - Dependencies all met for dep_context=non-requeueable deps ti=<TaskInstance: etl_pipeline.ingest_xlsx manual__2024-07-14T10:38:25.775716+00:00 [queued]>
[2024-07-14T10:38:30.391+0000] {taskinstance.py:2076} INFO - Dependencies all met for dep_context=requeueable deps ti=<TaskInstance: etl_pipeline.ingest_xlsx manual__2024-07-14T10:38:25.775716+00:00 [queued]>
[2024-07-14T10:38:30.391+0000] {taskinstance.py:2306} INFO - Starting attempt 1 of 2
[2024-07-14T10:38:30.423+0000] {taskinstance.py:2330} INFO - Executing <Task(PythonOperator): ingest_xlsx> on 2024-07-14 10:38:25.775716+00:00
[2024-07-14T10:38:30.472+0000] {warnings.py:112} WARNING - /home/***/.local/lib/python3.12/site-packages/***/task/task_runner/standard_task_runner.py:61: DeprecationWarning: This process (pid=72) is multi-threaded, use of fork() may lead to deadlocks in the child.
  pid = os.fork()

[2024-07-14T10:38:30.478+0000] {standard_task_runner.py:63} INFO - Started process 76 to run task
[2024-07-14T10:38:30.480+0000] {standard_task_runner.py:90} INFO - Running: ['***', 'tasks', 'run', 'etl_pipeline', 'ingest_xlsx', 'manual__2024-07-14T10:38:25.775716+00:00', '--job-id', '162', '--raw', '--subdir', 'DAGS_FOLDER/demo.py', '--cfg-path', '/tmp/tmpreab2itd']
[2024-07-14T10:38:30.486+0000] {standard_task_runner.py:91} INFO - Job 162: Subtask ingest_xlsx
[2024-07-14T10:38:30.712+0000] {task_command.py:426} INFO - Running <TaskInstance: etl_pipeline.ingest_xlsx manual__2024-07-14T10:38:25.775716+00:00 [running]> on host 37d6808b0cee
[2024-07-14T10:38:31.108+0000] {taskinstance.py:2648} INFO - Exporting env vars: AIRFLOW_CTX_DAG_EMAIL='your_email@example.com' AIRFLOW_CTX_DAG_OWNER='***' AIRFLOW_CTX_DAG_ID='etl_pipeline' AIRFLOW_CTX_TASK_ID='ingest_xlsx' AIRFLOW_CTX_EXECUTION_DATE='2024-07-14T10:38:25.775716+00:00' AIRFLOW_CTX_TRY_NUMBER='1' AIRFLOW_CTX_DAG_RUN_ID='manual__2024-07-14T10:38:25.775716+00:00'
[2024-07-14T10:38:31.113+0000] {taskinstance.py:430} INFO - ::endgroup::
[2024-07-14T10:38:31.157+0000] {taskinstance.py:441} INFO - ::group::Post task execution logs
[2024-07-14T10:38:31.158+0000] {taskinstance.py:2905} ERROR - Task failed with exception
Traceback (most recent call last):
  File "/home/airflow/.local/lib/python3.12/site-packages/airflow/models/taskinstance.py", line 465, in _execute_task
    result = _execute_callable(context=context, **execute_callable_kwargs)
             ^^^^^^^^^^^^^^^^^^^^^^^^^^^^^^^^^^^^^^^^^^^^^^^^^^^^^^^^^^^^^
  File "/home/airflow/.local/lib/python3.12/site-packages/airflow/models/taskinstance.py", line 432, in _execute_callable
    return execute_callable(context=context, **execute_callable_kwargs)
           ^^^^^^^^^^^^^^^^^^^^^^^^^^^^^^^^^^^^^^^^^^^^^^^^^^^^^^^^^^^^
  File "/home/airflow/.local/lib/python3.12/site-packages/airflow/models/baseoperator.py", line 401, in wrapper
    return func(self, *args, **kwargs)
           ^^^^^^^^^^^^^^^^^^^^^^^^^^^
  File "/home/airflow/.local/lib/python3.12/site-packages/airflow/operators/python.py", line 235, in execute
    return_value = self.execute_callable()
                   ^^^^^^^^^^^^^^^^^^^^^^^
  File "/home/airflow/.local/lib/python3.12/site-packages/airflow/operators/python.py", line 252, in execute_callable
    return self.python_callable(*self.op_args, **self.op_kwargs)
           ^^^^^^^^^^^^^^^^^^^^^^^^^^^^^^^^^^^^^^^^^^^^^^^^^^^^^
  File "/opt/airflow/dags/demo.py", line 20, in ingest_xlsx
    df_xlsx = pd.read_csv(xlsx_path)
              ^^^^^^^^^^^^^^^^^^^^^^
  File "/home/airflow/.local/lib/python3.12/site-packages/pandas/io/parsers/readers.py", line 948, in read_csv
    return _read(filepath_or_buffer, kwds)
           ^^^^^^^^^^^^^^^^^^^^^^^^^^^^^^^
  File "/home/airflow/.local/lib/python3.12/site-packages/pandas/io/parsers/readers.py", line 611, in _read
    parser = TextFileReader(filepath_or_buffer, **kwds)
             ^^^^^^^^^^^^^^^^^^^^^^^^^^^^^^^^^^^^^^^^^^
  File "/home/airflow/.local/lib/python3.12/site-packages/pandas/io/parsers/readers.py", line 1448, in __init__
    self._engine = self._make_engine(f, self.engine)
                   ^^^^^^^^^^^^^^^^^^^^^^^^^^^^^^^^^
  File "/home/airflow/.local/lib/python3.12/site-packages/pandas/io/parsers/readers.py", line 1723, in _make_engine
    return mapping[engine](f, **self.options)
           ^^^^^^^^^^^^^^^^^^^^^^^^^^^^^^^^^^
  File "/home/airflow/.local/lib/python3.12/site-packages/pandas/io/parsers/c_parser_wrapper.py", line 93, in __init__
    self._reader = parsers.TextReader(src, **kwds)
                   ^^^^^^^^^^^^^^^^^^^^^^^^^^^^^^^
  File "parsers.pyx", line 579, in pandas._libs.parsers.TextReader.__cinit__
  File "parsers.pyx", line 668, in pandas._libs.parsers.TextReader._get_header
  File "parsers.pyx", line 879, in pandas._libs.parsers.TextReader._tokenize_rows
  File "parsers.pyx", line 890, in pandas._libs.parsers.TextReader._check_tokenize_status
  File "parsers.pyx", line 2050, in pandas._libs.parsers.raise_parser_error
  File "<frozen codecs>", line 322, in decode
UnicodeDecodeError: 'utf-8' codec can't decode byte 0xe1 in position 966: invalid continuation byte
[2024-07-14T10:38:31.231+0000] {taskinstance.py:1206} INFO - Marking task as UP_FOR_RETRY. dag_id=etl_pipeline, task_id=ingest_xlsx, run_id=manual__2024-07-14T10:38:25.775716+00:00, execution_date=20240714T103825, start_date=20240714T103830, end_date=20240714T103831
[2024-07-14T10:38:31.292+0000] {standard_task_runner.py:110} ERROR - Failed to execute job 162 for task ingest_xlsx ('utf-8' codec can't decode byte 0xe1 in position 966: invalid continuation byte; 76)
[2024-07-14T10:38:31.360+0000] {local_task_job_runner.py:240} INFO - Task exited with return code 1
[2024-07-14T10:38:31.454+0000] {taskinstance.py:3503} INFO - 0 downstream tasks scheduled from follow-on schedule check
[2024-07-14T10:38:31.469+0000] {local_task_job_runner.py:222} INFO - ::endgroup::
